Workbook
Name Arjosari: 'Data Desa'!$B$2:$B$18
Name ASPEK: 'Data Aspek'!$A$2:$A$6
Name Bandar: 'Data Desa'!$C$2:$C$9
Name Desa_Arjosari: 'Data Desa'!$N$2:$N$24
Name Desa_Arjowinangun: 'Data Desa'!$CS$2:$CS$24
Name Desa_Bandar: 'Data Desa'!$AE$2:$AE$24
Name Desa_Bangunsari__Bandar: 'Data Desa'!$AF$2:$AF$24
Name Desa_Bangunsari__Pacitan: 'Data Desa'!$CU$2:$CU$24
Name Desa_Banjarjo: 'Data Desa'!$AY$2:$AY$24
Name Desa_Banjarsari: 'Data Desa'!$CV$2:$CV$24
Name Desa_Belah: 'Data Desa'!$AM$2:$AM$24
Name Desa_Bodag: 'Data Desa'!$CA$2:$CA$24
Name Desa_Bogoharjo: 'Data Desa'!$CB$2:$CB$24
Name Desa_Bolosingo: 'Data Desa'!$CW$2:$CW$24
Name Desa_Bomo: 'Data Desa'!$EE$2:$EE$24
Name Desa_Borang: 'Data Desa'!$O$2:$O$24
Name Desa_Bubakan: 'Data Desa'!$FM$2:$FM$24
Name Desa_Bungur: 'Data Desa'!$FN$2:$FN$24
Name Desa_Candi: 'Data Desa'!$DR$2:$DR$24
Name Desa_Cangkring: 'Data Desa'!$CC$2:$CC$24
Name Desa_Cemeng: 'Data Desa'!$AN$2:$AN$24
Name Desa_Cokrokembang: 'Data Desa'!$CD$2:$CD$24
Name Desa_Dadapan: 'Data Desa'!$DS$2:$DS$24
Name Desa_Dersono: 'Data Desa'!$DT$2:$DT$24
Name Desa_Donorojo: 'Data Desa'!$AO$2:$AO$24
Name Desa_Gasang: 'Data Desa'!$FO$2:$FO$24
Name Desa_Gawang: 'Data Desa'!$AZ$2:$AZ$24
Name Desa_Gayuhan: 'Data Desa'!$P$2:$P$24
Name Desa_Gedangan: 'Data Desa'!$FB$2:$FB$24
Name Desa_Gedompol: 'Data Desa'!$AP$2:$AP$24
Name Desa_Gegeran: 'Data Desa'!$Q$2:$Q$24
Name Desa_Gemaharjo: 'Data Desa'!$FC$2:$FC$24
Name Desa_Gembong: 'Data Desa'!$R$2:$R$24
Name Desa_Gembuk: 'Data Desa'!$BA$2:$BA$24
Name Desa_Gendaran: 'Data Desa'!$AQ$2:$AQ$24
Name Desa_Glinggangan: 'Data Desa'!$DU$2:$DU$24
Name Desa_Gondang: 'Data Desa'!$BR$2:$BR$24
Name Desa_Gondosari: 'Data Desa'!$EF$2:$EF$24
Name Desa_Gunung_Rejo: 'Data Desa'!$ER$2:$ER$24
Name Desa_Gunungsari: 'Data Desa'!$S$2:$S$24
Name Desa_Hadiluwih: 'Data Desa'!$CE$2:$CE$24
Name Desa_Hadiwarno: 'Data Desa'!$CF$2:$CF$24
Name Desa_Jatigunung: 'Data Desa'!$FP$2:$FP$24
Name Desa_Jatimalang: 'Data Desa'!$T$2:$T$24
Name Desa_Jeruk: 'Data Desa'!$AG$2:$AG$24
Name Desa_Jetak: 'Data Desa'!$FQ$2:$FQ$24
Name Desa_Jetis_Kidul: 'Data Desa'!$U$2:$U$24
Name Desa_Jetislor: 'Data Desa'!$BS$2:$BS$24
Name Desa_Jlubang: 'Data Desa'!$DV$2:$DV$24
Name Desa_Kalak: 'Data Desa'!$AR$2:$AR$24
Name Desa_Kalikuning: 'Data Desa'!$FR$2:$FR$24
Name Desa_Kalipelus: 'Data Desa'!$BB$2:$BB$24
Name Desa_Karang_Mulyo: 'Data Desa'!$ES$2:$ES$24
Name Desa_Karanganyar: 'Data Desa'!$BC$2:$BC$24
Name Desa_Karanggede: 'Data Desa'!$V$2:$V$24
Name Desa_Karangnongko: 'Data Desa'!$BD$2:$BD$24
Name Desa_Karangrejo: 'Data Desa'!$W$2:$W$24
Name Desa_Kasihan: 'Data Desa'!$FD$2:$FD$24
Name Desa_Katipugal: 'Data Desa'!$BE$2:$BE$24
Name Desa_Kayen: 'Data Desa'!$CX$2:$CX$24

Sheet Data Desa
A1: Kecamatan | B1: Arjosari | C1: Bandar | D1: Donorojo | E1: Kebonagung | F1: Nawangan | G1: Ngadirojo | H1: Pacitan | I1: Pringkuku | J1: Punung | K1: Sudimoro | L1: Tegalombo | M1: Tulakan | N1: Desa Arjosari | O1: Desa Borang | P1: Desa Gayuhan | Q1: Desa Gegeran | R1: Desa Gembong | S1: Desa Gunungsari | T1: Desa Jatimalang | U1: Desa Jetis Kidul | V1: Desa Karanggede | W1: Desa Karangrejo | X1: Desa Kedungbendo | Y1: Desa Mangunharjo | Z1: Desa Mlati | AA1: Desa Pagutan | AB1: Desa Sedayu | AC1: Desa Temon | AD1: Desa Tremas | AE1: Desa Bandar | AF1: Desa Bangunsari Bandar | AG1: Desa Jeruk | AH1: Desa Kledung | AI1: Desa Ngunut | AJ1: Desa Petungsinarang | AK1: Desa Tumpuk | AL1: Desa Watupatok | AM1: Desa Belah | AN1: Desa Cemeng | AO1: Desa Donorojo | AP1: Desa Gedompol | AQ1: Desa Gendaran | AR1: Desa Kalak | AS1: Desa Klepu Donorojo | AT1: Desa Sawahan | AU1: Desa Sekar | AV1: Desa Sendang | AW1: Desa Sukodono | AX1: Desa Widoro (Donorojo) | AY1: Desa Banjarjo | AZ1: Desa Gawang | BA1: Desa Gembuk | BB1: Desa Kalipelus | BC1: Desa Karanganyar | BD1: Desa Karangnongko | BE1: Desa Katipugal | BF1: Desa Kebonagung | BG1: Desa Ketepung | BH1: Desa Ketro (Kebonagung) | BI1: Desa Klesem | BJ1: Desa Mantren (Kebonagung) | BK1: Desa Plumbungan | BL1: Desa Punjung | BM1: Desa Purwoasri | BN1: Desa Sanggrahan | BO1: Desa Sidomulyo (Kebonagung) | BP1: Desa Wonogondo | BQ1: Desa Worawari | BR1: Desa Gondang | BS1: Desa Jetislor | BT1: Desa Mujing | BU1: Desa Nawangan | BV1: Desa Ngromo | BW1: Desa Pakisbaru | BX1: Desa Penggung | BY1: Desa Sempu | BZ1: Desa Tokawi | CA1: Desa Bodag | CB1: Desa Bogoharjo | CC1: Desa Cangkring | CD1: Desa Cokrokembang | CE1: Desa Hadiluwih | CF1: Desa Hadiwarno | CG1: Desa Ngadirojo | CH1: Desa Nogosari | CI1: Desa Pagerejo | CJ1: Desa Sidomulyo (Ngadirojo) | CK1: Desa Tanjunglor | CL1: Desa Tanjungpuro | CM1: Desa Wiyoro | CN1: Desa Wonoasri | CO1: Desa Wonodadi Kulon | CP1: Desa Wonodadi Wetan | CQ1: Desa Wonokarto | CR1: Desa Wonosobo | CS1: Desa Arjowinangun | CT1: Kelurahan Baleharjo | CU1: Desa Bangunsari (Pacitan) | CV1: Desa Banjarsari | CW1: Desa Bolosingo | CX1: Desa Kayen | CY1: Desa Kembang | CZ1: Desa Menadi | DA1: Desa Mentoro | DB1: Desa Nanggungan | DC1: Kelurahan Pacitan | DD1: Kelurahan Ploso | DE1: Desa Ponggok | DF1: Kelurahan Pucangsewu | DG1: Desa Purworejo | DH1: Desa Sambong | DI1: Desa Sedeng | DJ1: Desa Semanten | DK1: Kelurahan Sidoharjo | DL1: Desa Sirnoboyo | DM1: Desa Sukoharjo | DN1: Desa Sumberharjo | DO1: Desa Tambakrejo | DP1: Desa Tanjungsari | DQ1: Desa Widoro (Pacitan) | DR1: Desa Candi | DS1: Desa Dadapan | DT1: Desa Dersono | DU1: Desa Glinggangan | DV1: Desa Jlubang | DW1: Desa Ngadirejan | DX1: Desa Pelem | DY1: Desa Poko | DZ1: Desa Pringkuku | EA1: Desa Sobo | EB1: Desa Sugihwaras | EC1: Desa Tamanasri | ED1: Desa Watu Karung | EE1: Desa Bomo | EF1: Desa Gondosari | EG1: Desa Kebonsari | EH1: Desa Kendal | EI1: Desa Mantren (Punung) | EJ1: Desa Mendolo Kidul | EK1: Desa Mendolo Lor | EL1: Desa Piton | EM1: Desa Ploso (Punung) | EN1: Desa Punung | EO1: Desa Sooka | EP1: Desa Tinatar | EQ1: Desa Wareng | ER1: Desa Gunung Rejo | ES1: Desa Karang Mulyo | ET1: Desa Ketanggung | EU1: Desa Klepu (Sudimoro) | EV1: Desa Pager Kidul | EW1: Desa Pager Lor | EX1: Desa Sembowo | EY1: Desa Sudimoro | EZ1: Desa Sukorejo | FA1: Desa Sumber Rejo | FB1: Desa Gedangan | FC1: Desa Gemaharjo | FD1: Desa Kasihan | FE1: Desa Kebondalem | FF1: Desa Kemuning | FG1: Desa Ngreco | FH1: Desa Ploso (Tegalombo) | FI1: Desa Pucangombo | FJ1: Desa Tahunan | FK1: Desa Tahunan Baru | FL1: Desa Tegalombo | FM1: Desa Bubakan | FN1: Desa Bungur | FO1: Desa Gasang | FP1: Desa Jatigunung | FQ1: Desa Jetak | FR1: Desa Kalikuning | FS1: Desa Ketro (Tulakan) | FT1: Desa Ketro Harjo | FU1: Desa Kluwih | FV1: Desa Losari | FW1: Desa Ngile | FX1: Desa Nglaran | FY1: Desa Ngumbul | FZ1: Desa Padi | GA1: Desa Tulakan | GB1: Desa Wonoanti | GC1: Desa Wonosidi
A2: Arjosari | B2: Desa Arjosari | C2: Desa Bandar | D2: Desa Belah | E2: Desa Banjarjo | F2: Desa Gondang | G2: Desa Bodag | H2: Desa Arjowinangun | I2: Desa Candi | J2: Desa Bomo | K2: Desa Gunung Rejo | L2: Desa Gedangan | M2: Desa Bubakan | N2: KWT Ngudi Rejeki Lancar | O2: KWT Sido Lestari | P2: KWT Gayuh Sehat I | Q2: KWT Tani Maju | R2: KWT Sumber Urip I | S2: KWT Dahlia | T2: KWT Eka Mandiri | U2: Sido Subur I | V2: KWT Mawar | W2: Sumber Urip I | X2: KWT Sido Makmur | Y2: KWT Dahlia | Z2: KWT SEKAR TANJUNG | AA2: KWT MAWAR | AB2: MAKMUR RUKUN I | AC2: AKUR I | AD2: KWT PERTIWI | AE2: BINTANG TIMUR | AF2: BLIMBING TANI | AG2: BUDI LUHUR | AH2: BLOROK MADU | AI2: KWT. MELATI | AJ2: KENANGA I | AK2: ANGGIAT TANI | AL2: DADI MAKMUR | AM2: Dadi Makmur | AN2: Edi Peni | AO2: Jati Diri | AP2: Budi Lestari | AQ2: Dadi Mulyo | AR2: KWT. KELAPA SARI | AS2: Loh Jinawi | AT2: Bakti Tani | AU2: KWT Sekar Arum Sejahtera | AV2: Gebang Wonokarto | AW2: Assalam | AX2: Lestari | AY2: Sumber Makmur 1 | AZ2: Setyo Maju 1 | BA2: Tri Karsa 1 | BB2: Tani Maju 1 | BC2: Gotong Royong 1 | BD2: Sedyo Makmur 1 | BE2: Pratolo Mulyo 1 | BF2: Mentes 1 | BG2: Sido Mekar 1 | BH2: Sido Maju 1 | BI2: Sari Tani 1 | BJ2: Margo Subur 1 | BK2: Lestari I | BL2: Ngudi Makmur 1 | BM2: Sumber Asri 1 | BN2: Setya Usaha I | BO2: Bumi Harum 1 | BP2: Sido Rejo 1 | BQ2: Sido Makmur 1 | BR2: Dewi Sinto | BS2: Dewi Sri | BT2: Karya Makmur I | BU2: Ledok Sari | BV2: Arum Tani | BW2: BARU WUNGU | BX2: Karya Makmur | BY2: Berkah Tani | BZ2: Gemah Ripah | CA2: NGUDI LUHUR I | CB2: KWT MARDI RAHAYU | CC2: SUKODONO I | CD2: RUKUN MAKMUR I | CE2: Melati | CF2: Matahari | CG2: MEKARSARI I | CH2: KARYA MULYA I | CI2: BANGUNREJO I | CJ2: KWT. LESTARI MULYO | CK2: MARGO RUKUN I | CL2: MAKMUR I | CM2: MARDI REJO I | CN2: ERAS ASRI I | CO2: DHARMA BAKTI | CP2: SIDO MAKMUR I | CQ2: ERAS I | CR2: ERAS SOBO 5 | CS2: Sido Asih I | CT2: Eko Proyo I | CU2: Gemah Ripah I | CV2: KWT Melati | CW2: Utama Karya I | CX2: KWT Karya Makmur | CY2: Sido Mekar 1 | CZ2: KWT SRIKANDI | DA2: Sedyo Tani I | DB2: KWT PADEMANGAN PUTRI | DC2: MANUNGGAL I | DD2: KWT Margo Makmur VI A | DE2: SIDO MAKMUR I | DF2: KARYO TOMO I | DG2: KWT Sido Dadi | DH2: ARGO MULYO I | DI2: Mekar Sari I | DJ2: Mugi Rahayu I | DK2: KWT Bina Makmur | DL2: KWT Mekar Sari | DM2: KWT Sido Rukun | DN2: KWT Rejo Mulyo | DO2: Karya Tani I | DP2: Karya Tunggal I | DQ2: KWT SIDO MAPAN | DR2: Nuju Makmur 01 | DS2: Suka Maju 01 | DT2: Sakti I | DU2: Margo Mulyo 01 | DV2: Selo Rejeki I | DW2: Blimbing Sari | DX2: Sri Rejeki I | DY2: Lestari I | DZ2: JANTI MAKMUR | EA2: Sido Mulyo I | EB2: Gemah Ripah I | EC2: SIDO MULYO SEPULUH | ED2: KWT Sido Mukti 4 | EE2: KWT Manunggal Mukti | EF2: Maju Lancar | EG2: Harapan | EH2: Tani Harapan | EI2: Fajar Rahayu | EJ2: Karya Luhur I | EK2: Basuki Makmur | EL2: Budi Luhur | EM2: Amanah | EN2: Karya Tani | EO2: Mardi Utomo | EP2: Ayem Tentrem | EQ2: Eko Budoyo | ER2: MEKAR SARI 1 | ES2: KWT. SRI TANJUNG | ET2: Sedya Mulya 1 | EU2: BATU GUNA | EV2: Kutilang 1 | EW2: KARYA TANI | EX2: Margo Mulyo 1 | EY2: KWT. SRIKANDI | EZ2: KWT Kali Rejo | FA2: SIDO LANCAR | FB2: RUKUN TANI I | FC2: GEMAH RIPAH 1 | FD2: AMONG TANI I | FE2: SEDYO MAJU I | FF2: PUNCAK SEWU | FG2: KWT LUMBU INDAH | FH2: KARYA MAKMUR I | FI2: MANDIRI MAPAN | FJ2: AL-FATTAH | FK2: GONDO ARUM | FL2: HANDAYANI I | FM2: NGUDI BOGO I | FN2: KARYA TANI I | FO2: MARGO MAKMUR I | FP2: JATI MULYO 1 | FQ2: DARMA TANI I | FR2: KWT Sido Lancar | FS2: SUBUR MAKMUR 1 | FT2: HARJO MAKMUR 1 | FU2: SETYA KARYA DUA | FV2: MEKAR SARI 1 | FW2: EDI PENI I | FX2: KWT. JAMU SEGER MANIS | FY2: WALUYO ASIH I | FZ2: PADI WARAS 2 | GA2: NGUPADI HASIL 1 | GB2: GEMAH RIPAH 1 | GC2: BUDI KARYA 1
A3: Bandar | B3: Desa Borang | C3: Desa Bangunsari Bandar | D3: Desa Cemeng | E3: Desa Gawang | F3: Desa Jetislor | G3: Desa Bogoharjo | H3: Kelurahan Baleharjo | I3: Desa Dadapan | J3: Desa Gondosari | K3: Desa Karang Mulyo | L3: Desa Gemaharjo | M3: Desa Bungur | N3: Adil Makmur I | O3: Sido Rukun I | P3: KWT Gayuh Sehat II | Q3: Sido Dadi | R3: KWT Sumber Urip II | S3: KWT Melati Putih | T3: Lestari I | U3: Sido Subur II | V3: Tani Maju I | W3: Sumber Urip II | X3: Rukun III | Y3: Sido Mulyo I | Z3: SIDO MAKMUR I | AA3: Rukun Santosa 01 | AB3: MAKMUR RUKUN II | AC3: AKUR II | AD3: Guyup Rukun 01 | AE3: EDI PENI | AF3: CIPTO TANI | AG3: BUDI UTOMO | AH3: ENGGAL LESTARI | AI3: LESTARI | AJ3: KENANGA II | AK3: Kenanga | AL3: GUNUNG SARI DUA | AM3: Hasil Tani | AN3: Eko Makaryo | AO3: Karya Bakti | AP3: Mardi Makmur I | AQ3: KWT Karya Maju | AR3: Barokah | AS3: Makmur | AT3: Budi Luhur | AU3: Ngudi Rahayu | AV3: Makmur | AW3: Budi Mulyo | AX3: Ngudi Makmur | AY3: Sumber Makmur 2 | AZ3: Setyo Maju 3 | BA3: Tri Karsa 10 | BB3: Tani Maju 2 | BC3: Gotong Royong 2 | BD3: Sedyo Makmur 2 | BE3: Pratolo Mulyo 2 | BF3: Mentes 2 | BG3: Sido Mekar 2 | BH3: Sido Maju 2 | BI3: Sari Tani 2 | BJ3: Margo Subur 2 | BK3: Lestari II | BL3: Ngudi Makmur 2 | BM3: Sumber Asri 2 | BN3: Setya Usaha II | BO3: Bumi Harum 10 | BP3: Sido Rejo 2 | BQ3: Sido Makmur 2 | BR3: Dewi Sri | BS3: Dono Asih | BT3: Karya Makmur II | BU3: Manunggal Karya | BV3: Bina Tani I | BW3: HARGO MULYO | BX3: Lestari | BY3: Karya Muda | BZ3: Hidayah | CA3: NGUDI LUHUR II | CB3: MARDI RAHAYU I | CC3: SUKODONO II | CD3: RUKUN MAKMUR II | CE3: PENI | CF3: TUNAS HARAPAN I | CG3: MEKARSARI II | CH3: KARYA MULYA II | CI3: BANGUNREJO II | CJ3: WIDYASANA I | CK3: MARGO RUKUN II | CL3: MAKMUR II | CM3: MARDI REJO II | CN3: ERAS ASRI II | CO3: NGUDI MAKMUR I | CP3: SIDO MAKMUR II | CQ3: ERAS II | CR3: ERAS SOBO I | CS3: Sido Asih II | CT3: Eko Proyo II | CU3: Gemah Ripah II | CV3: Sido Dadi I | CW3: Utama Karya II | CX3: KWT Sumber Rejeki | CY3: Sido Mekar 2 | CZ3: Gemah Ripah I | DA3: Sedyo Tani II | DB3: Sedyo Rukun I | DC3: Manunggal II | DD3: Margo Makmur I | DE3: SIDO MAKMUR II | DF3: KARYO TOMO II | DG3: Margo Mulyo I | DH3: ARGO MULYO II | DI3: Mekar Sari II | DJ3: Mugi Rahayu II | DK3: KWT Mekar Makmur | DL3: Sido Maju I | DM3: Sido Rukun I | DN3: KWT Tani Maju | DO3: Karya Tani II | DP3: Karya Tunggal II | DQ3: Sidodadi I | DR3: Nuju Makmur II | DS3: Suka Maju 05 | DT3: Sakti II | DU3: Margo Mulyo 05 | DV3: Selo Rejeki II | DW3: KWT. Rindang | DX3: Sri Rejeki II | DY3: Lestari II | DZ3: Gondang Rejo I | EA3: Sido Mulyo II | EB3: Gemah Ripah II | EC3: KWT. Budi Lestari | ED3: KWT Sido Mukti I | EE3: Manunggal Mukti | EF3: Margo Dadi | EG3: Lestari | EH3: Tani Makmur | EI3: Handayani | EJ3: Karya Luhur II | EK3: Eko Karyo | EL3: Karya Tani | EM3: Hidayah | EN3: Maju Lancar I | EO3: Mardi Waluyo I | EP3: Bakti Utomo | EQ3: Ngudi Makmur | ER3: MEKAR SARI 2 | ES3: Margo Mulyo | ET3: Sedya Mulya 2 | EU3: LAJUR SEMPU 1 | EV3: Kutilang 2 | EW3: NGUDI MULYO 1 | EX3: Margo Mulyo 2 | EY3: Mijil Pangan | EZ3: KWT Marsudi Tani | FA3: Duren Manis 1 | FB3: RUKUN TANI II | FC3: GEMAH RIPAH 2 | FD3: AMONG TANI II | FE3: SEDYO MAJU II | FF3: SIDO MAKMUR I | FG3: SUMBER TANI I | FH3: KARYA MAKMUR II | FI3: MEKAR DADI | FJ3: BUMI RAHAYU | FK3: KWT LESTARI | FL3: HANDAYANI II | FM3: NGUDI BOGO II | FN3: KARYA TANI II | FO3: MARGO MAKMUR II | FP3: JATI MULYO 2 | FQ3: DARMA TANI II | FR3: MARGO MULYO 1 | FS3: SUBUR MAKMUR 2 | FT3: HARJO MAKMUR 2 | FU3: SETYA KARYA EMPAT | FV3: MEKAR SARI 2 | FW3: EDI PENI II | FX3: TANI MAKMUR 1 | FY3: WALUYO ASIH II | FZ3: PADI WARAS 3 | GA3: NGUPADI HASIL 2 | GB3: GEMAH RIPAH 2 | GC3: BUDI KARYA 2
A4: Donorojo | B4: Desa Gayuhan | C4: Desa Jeruk | D4: Desa Donorojo | E4: Desa Gembuk | F4: Desa Mujing | G4: Desa Cangkring | H4: Desa Bangunsari (Pacitan) | I4: Desa Dersono | J4: Desa Kebonsari | K4: Desa Ketanggung | L4: Desa Kasihan | M4: Desa Gasang | N4: Adil Makmur II | O4: Sido Rukun II | P4: Rukun Makmur I | Q4: Sido Makmur | R4: Sumber Urip I | S4: Margo Makmur I | T4: Lestari II | U4: Sido Subur III | V4: Tani Maju II | W4: Sumber Urip III | X4: Rukun Tani I | Y4: Sido Mulyo IB | Z4: SIDO MAKMUR II | AA4: Rukun Santosa III | AB4: MAKMUR RUKUN III | AC4: AKUR III | AD4: Guyup Rukun 02 | AE4: EKO SAYEKTI | AF4: DADI MAKMUR | AG4: GUNUNG SUBUR | AH4: JATI SARI | AI4: MAKMUR DUA | AJ4: SIDO DADI | AK4: MARGO MAKMUR DUA | AL4: GUNUNG SARI SATU | AM4: Karya Bima | AN4: Gawe Santoso | AO4: Karya Tani | AP4: Mardi Makmur II | AQ4: Margi Laras | AR4: Dadi Makmur | AS4: Margo Mulyo | AT4: Margo Mulyo | AU4: Sido Dadi I | AV4: Manunggal Bakti | AW4: Dadi Subur | AX4: Sido Makmur | AY4: Sumber Makmur 3 | AZ4: Setyo Maju 4 | BA4: Tri Karsa 11 | BB4: Tani Maju 3 | BC4: Gotong Royong 3 | BD4: Sedyo Makmur 3 | BE4: Pratolo Mulyo 3 | BF4: Mentes 3 | BG4: Sido Mekar 3 | BH4: Sido Maju 3 | BI4: Sari Tani 3 | BJ4: Margo Subur 3 | BK4: Lestari III | BL4: Ngudi Makmur 3 | BM4: Sumber Asri 3 | BN4: Setya Usaha III | BO4: Bumi Harum 11 | BP4: Sido Rejo 3 | BQ4: Sido Makmur 3 | BR4: Hargo Sedah | BS4: Indah Karya I | BT4: Margo Rahayu | BU4: Mawar | BV4: Bina Tani II | BW4: Lestari Mulyo | BX4: Ngudi Boga | BY4: Maju Tani | BZ4: Karya Makmur | CA4: NGUDI LUHUR III | CB4: MARDI RAHAYU II | CC4: SUKODONO III | CD4: RUKUN MAKMUR III | CE4: PENI I | CF4: TUNAS HARAPAN II | CG4: MEKARSARI III | CH4: KARYA MULYA III | CI4: BANGUNREJO III | CJ4: WIDYASANA II | CK4: MARGO RUKUN III | CL4: MAKMUR III | CM4: MARDI REJO III | CN4: ERAS ASRI III | CO4: NGUDI MAKMUR II | CP4: SIDO MAKMUR III | CQ4: ERAS III | CR4: ERAS SOBO II | CS4: Sido Asih III | CT4: KWT Sakura III | CU4: Gemah Ripah III | CV4: Sido Dadi II | CW4: Utama Karya III | CX4: Sumber Urip I | CY4: Sido Mekar 3 | CZ4: Gemah Ripah II | DA4: Sedyo Tani III | DB4: Sedyo Rukun II | DD4: Margo Makmur II | DE4: SIDO MAKMUR III | DG4: Margo Mulyo II | DH4: ARGO MULYO III | DI4: Mekar Sari III | DJ4: Mugi Rahayu III | DK4: Sido Makmur I | DL4: Sido Maju II | DM4: Sido Rukun II | DN4: Sumber Makmur I | DO4: Karya Tani III | DP4: Karya Tunggal III | DQ4: Sidodadi II | DR4: Nuju Makmur III | DS4: Suka Maju II | DT4: Sakti III | DU4: Margo Mulyo II | DV4: Selo Rejeki III | DW4: Sumber Rejeki Dua | DX4: Sri Rejeki III | DY4: Lestari III | DZ4: Gondang Rejo II | EA4: Sido Mulyo III | EB4: Gemah Ripah III | EC4: Sido Mulyo II | ED4: Margo Mukti | EE4: Marsudi Tani | EF4: Margo Tani | EG4: Ngudi Makmur | EH4: Tani Mulyo | EI4: Ngudi Rukun | EJ4: Karya Tani | EK4: Handayani | EL4: Rukun Tani | EM4: Kurnia | EN4: Maju Lancar II | EO4: Mardi Waluyo II | EP4: Budi Lestari | EQ4: Sido Dadi | ER4: MEKAR SARI 3 | ES4: Margo Rukun | ET4: Sedya Mulya 3 | EU4: LAJUR SEMPU 2 | EV4: Lumpang Bogo 1 | EW4: NGUDI MULYO 2 | EX4: Margo Mulyo 3 | EY4: Ngudi Makmur | EZ4: MARSUDI TANI 1 | FA4: Duren Manis 2 | FB4: RUKUN TANI III | FC4: GEMAH RIPAH 3 | FD4: AMONG TANI III | FE4: SEDYO MAJU III | FF4: SIDO MAKMUR II | FG4: SUMBER TANI II | FH4: KARYA MAKMUR III | FI4: RUKUN TANI 2 | FJ4: KARYA MAKMUR I | FK4: SIDO RUKUN I | FL4: HANDAYANI IV | FM4: NGUDI BOGO III | FN4: KARYA TANI III | FO4: MARGO MAKMUR III | FP4: JATI MULYO 3 | FQ4: DARMA TANI III | FR4: Margo Mulyo 10 | FS4: SUBUR MAKMUR IV | FT4: HARJO MAKMUR 3 | FU4: SETYA KARYA SATU | FV4: MEKAR SARI 3 | FW4: EDI PENI III | FX4: TANI MAKMUR II | FY4: WALUYO ASIH III | FZ4: PADI WARAS 4 | GA4: NGUPADI HASIL 3 | GB4: GEMAH RIPAH 3 | GC4: BUDI KARYA 3
A5: Kebonagung | B5: Desa Gegeran | C5: Desa Kledung | D5: Desa Gedompol | E5: Desa Kalipelus | F5: Desa Nawangan | G5: Desa Cokrokembang | H5: Desa Banjarsari | I5: Desa Glinggangan | J5: Desa Kendal | K5: Desa Klepu (Sudimoro) | L5: Desa Kebondalem | M5: Desa Jatigunung | N5: Adil Makmur III | O5: Sido Rukun III | P5: Rukun Makmur II | Q5: Sido Mulyo | R5: Sumber Urip II | S5: Margo Makmur II | T5: Lestari III | U5: Sido Subur IV | V5: Tani Maju III | W5: Sumber Urip IV | X5: Rukun Tani II | Y5: Sido Mulyo II | Z5: SIDO MAKMUR III | AA5: Rukun Santosa IV | AB5: MAKMUR RUKUN IV | AC5: AKUR IV | AD5: Guyup Rukun 03 | AE5: GUNUNG SUBUR | AF5: ENDAH PENI | AG5: HARGO MAKMUR | AH5: KARYA TUNGGAL | AI5: MAKMUR SATU | AJ5: SIDO DADI 1 | AK5: MARGO MAKMUR SATU | AL5: MEKAR DADI | AM5: Karya Makmur | AN5: Gotong Royong | AO5: KWT Mekar Sari | AP5: Mardi Makmur III | AQ5: Margo Mulyo | AR5: Dadi Mulyo | AS5: Mekar Sari | AT5: Rukun Makmur | AU5: Sido Dadi II | AV5: Rukun Tani | AW5: Giri Mulyo | AX5: Sido Tani | AY5: Sumber Makmur 4 | AZ5: Setyo Maju 5 | BA5: Tri Karsa 2 | BB5: Tani Maju 4 | BC5: Gotong Royong 4 | BD5: Sedyo Makmur 4 | BE5: Pratolo Mulyo 4 | BG5: Sido Mekar 4 | BH5: Sido Maju 4 | BI5: Sari Tani 4 | BJ5: Margo Subur 4 | BK5: Lestari IV | BL5: Ngudi Makmur 4 | BM5: Sumber Asri 4 | BN5: Setya Usaha IV | BO5: Bumi Harum 12 | BP5: Sido Rejo 4 | BQ5: Sido Makmur 4 | BR5: Karya Mandiri | BS5: Karya Bakti | BT5: Margo Rahayu 2 | BU5: Nawanggono | BV5: Bina Tani III | BW5: MARGO MULYO | BX5: Ngudi Luhur | BY5: MARSUDI SUBUR | BZ5: Karya Tani | CA5: NGUDI LUHUR IV | CB5: MARDI RAHAYU III | CC5: SUKODONO IV | CD5: RUKUN MAKMUR IV | CE5: PENI II | CF5: TUNAS HARAPAN III | CG5: MEKARSARI IV | CH5: KARYA MULYA IV | CI5: BANGUNREJO IV | CJ5: WIDYASANA III | CK5: MARGO RUKUN IV | CL5: MAKMUR IV | CM5: MARDI REJO IV | CN5: ERAS ASRI IV | CO5: NGUDI MAKMUR III | CP5: SIDO MAKMUR IV | CQ5: ERAS IV | CR5: ERAS SOBO III | CS5: Sido Asih IV | CU5: Gemah Ripah IV | CV5: Sido Dadi III | CW5: Utama Karya IV | CX5: Sumber Urip II | CY5: Sido Mekar 4 | CZ5: Gemah Ripah III | DB5: Sedyo Rukun III | DD5: Margo Makmur III | DE5: SIDO MAKMUR IV | DG5: Margo Mulyo III | DH5: ARGO MULYO IV | DI5: Mekar Sari IV | DJ5: Mugi Rahayu IV | DK5: Sido Makmur II | DL5: Sido Maju III | DM5: Sido Rukun III | DN5: Sumber Makmur II | DO5: KWT Dewi Sri | DP5: KWT Sri Tanjung | DQ5: Sidodadi III | DR5: Nuju Makmur IV | DS5: Suka Maju III | DT5: Sakti IV | DU5: Margo Mulyo III | DV5: Selo Rejeki IV | DW5: Sumber Rejeki III | DX5: Sri Rejeki IV | DY5: Lestari IV | DZ5: Gondang Rejo V | EA5: Sido Mulyo IV | EB5: Gemah Ripah IX | EC5: Sido Mulyo III | ED5: Sido Mukti I | EE5: Mekar Sari | EF5: Rahayu | EG5: Sido Dadi | EH5: Tani Murni | EI5: Rukun Mulyo | EJ5: Margo Tresno | EK5: Karya Bakti | EL5: Sido Luhur | EM5: Margo Asih | EN5: Margo Mulyo | EO5: Margo Gesang | EP5: Karya Makmur | EQ5: Sido Makmur | ER5: SUMBER REJEKI 1 | ES5: Sido Dadi 1 | ET5: Sedya Mulya 4 | EU5: LAJUR SEMPU 3 | EV5: Lumpang Bogo 2 | EW5: NGUDI TANI | EX5: Margo Mulyo 4 | EY5: Ngudi Mulyo 1 | EZ5: MARSUDI TANI 2 | FA5: KWT Ngudi Rahayu | FC5: GEMAH RIPAH 4 | FD5: AMONG TANI IV | FE5: SEDYO MAJU IV | FF5: SIDO MAKMUR IV | FG5: SUMBER TANI III | FH5: KARYA MAKMUR IV | FI5: RUKUN TANI 3 | FJ5: KARYA MAKMUR II | FK5: SIDO RUKUN II | FL5: HANDAYANI V | FM5: NGUDI BOGO IV | FN5: KARYA TANI IV | FP5: JATI MULYO 4 | FQ5: DARMA TANI IV | FR5: MARGO MULYO 2 | FS5: SUBUR MAKMUR IX | FT5: HARJO MAKMUR 4 | FU5: SETYA KARYA TIGA | FV5: MEKAR SARI 4 | FW5: EDI PENI IV | FX5: TANI MAKMUR III | FY5: WALUYO ASIH IV | FZ5: PADI WARAS 5 | GA5: NGUPADI HASIL 4 | GB5: GEMAH RIPAH 4 | GC5: BUDI KARYA 4
A6: Nawangan | B6: Desa Gembong | C6: Desa Ngunut | D6: Desa Gendaran | E6: Desa Karanganyar | F6: Desa Ngromo | G6: Desa Hadiluwih | H6: Desa Bolosingo | I6: Desa Jlubang | J6: Desa Mantren (Punung) | K6: Desa Pager Kidul | L6: Desa Kemuning | M6: Desa Jetak | N6: Adil Makmur IV | O6: Sri Mulyo | P6: Rukun Makmur III | R6: Sumber Urip III | S6: Margo Makmur III | T6: Lestari IV | V6: Tani Maju IV | W6: Sumber Urip V | X6: Rukun Tani IV | Y6: Sido Mulyo III | Z6: SIDO MAKMUR IV | AA6: Rukun Santosa V | AB6: MAKMUR RUKUN IX | AC6: AKUR IX | AD6: Guyup Rukun 04 | AE6: GUNUNG SUBUR I | AF6: HAYATI | AG6: KAMBOJA | AH6: MAJU MAKMUR | AI6: MAKMUR TIGA | AJ6: SIDO MAJU | AK6: MARGO MAKMUR TIGA | AL6: MEKAR SARI | AM6: Karya Makmur I | AN6: Maju Lancar | AO6: Maju Lancar | AP6: Murih Widodo | AQ6: Ngudi Mulyo | AR6: Kelapa Sari | AS6: Ngudi Bogo | AT6: Sido Mukti | AU6: Sri Rejeki I | AV6: Sedya Maju | AW6: Karya Tani | AX6: Subur | AY6: Sumber Makmur 5 | AZ6: Setyo Maju 6 | BA6: Tri Karsa 3 | BB6: Tani Maju 5 | BC6: Gotong Royong 5 | BD6: Sedyo Makmur 5 | BE6: Pratolo Mulyo 5 | BG6: Sido Mekar 5 | BH6: Sido Maju 5 | BI6: Sari Tani 5 | BJ6: Margo Subur 5 | BL6: Ngudi Makmur 5 | BM6: Sumber Asri 5 | BN6: Setya Usaha V | BO6: Bumi Harum 13 | BP6: Sido Rejo 5 | BQ6: Sido Makmur 5 | BR6: Mawar Putih | BS6: Kundang Makmur | BT6: Margo Utomo | BU6: Nawanggono II | BV6: Karya Tani | BW6: MITRA TANI | BX6: Rukun Tani I | BY6: Marsudi Tani | BZ6: Maju Lancar | CA6: NGUDI LUHUR V | CB6: MARDI RAHAYU IV | CD6: RUKUN MAKMUR V | CE6: PENI III | CF6: TUNAS HARAPAN IV | CG6: MEKARSARI V | CH6: KARYA MULYA V | CI6: BANGUNREJO IX | CJ6: WIDYASANA IV | CK6: MARGO RUKUN V | CL6: Seruni | CM6: MARDI REJO V | CN6: ERAS ASRI V | CO6: NGUDI MAKMUR IV | CP6: SIDO MAKMUR V | CQ6: ERAS V | CR6: ERAS SOBO IV | CU6: Gemah Ripah V | CX6: Sumber Urip III | CY6: Sido Mekar 5 | CZ6: Gemah Ripah IV | DB6: Sedyo Rukun IV | DD6: Margo Makmur IV | DE6: SIDO MAKMUR V | DH6: ARGO MULYO IX | DI6: Mekar Sari V | DJ6: Mugi Rahayu V | DK6: Sido Makmur III | DL6: Sido Maju IV | DN6: Sumber Makmur III | DO6: KWT Srikandi | DR6: Nuju Makmur IX | DS6: Suka Maju IV | DT6: Sakti IX | DU6: Margo Mulyo IV | DV6: Selo Rejeki IX | DW6: Sumber Rejeki IV | DX6: Sri Rejeki IX | DY6: Lestari V | DZ6: Gondang Rejo VIII | EA6: Sido Mulyo V | EB6: Gemah Ripah VI | EC6: Sido Mulyo IV | ED6: Sido Mukti II | EE6: Ratih Tani | EF6: Sedyo Mulyo | EG6: Sumber Rejeki | EI6: Rukun Mulyo 2 | EJ6: Rebo Kliwon I | EK6: Karya Makmur | EL6: Sido Makmur | EM6: Margo Mulyo | EN6: Mekar Sari | EO6: Ngudi Lestari | EP6: Rejo Mulyo | EQ6: Sido Mulyo | ER6: SUMBER REJEKI 2 | ES6: Sido Dadi 2 | ET6: Sedya Mulya 5 | EU6: LAJUR SEMPU 4 | EV6: Pagergunung 1 | EW6: SEDYO MAKMUR | EX6: Margo Mulyo 5 | EY6: Ngudi Mulyo 2 | EZ6: NGUDI RAHAYU 1 | FA6: Makmur Lestari | FC6: GEMAH RIPAH 5 | FD6: AMONG TANI IX | FE6: SEDYO MAJU V | FF6: SIDO RUKUN II | FG6: SUMBER TANI IV | FH6: KARYA MAKMUR V | FI6: RUKUN TANI 4 | FJ6: KARYA MAKMUR III | FK6: SIDO RUKUN III | FL6: HANDAYANI VI | FM6: NGUDI BOGO V | FN6: KARYA TANI V | FP6: JATI MULYO 5 | FQ6: DARMA TANI V | FR6: MARGO MULYO 3 | FS6: SUBUR MAKMUR VII | FT6: HARJO MAKMUR 5 | FV6: MEKAR SARI 5 | FW6: EDI PENI V | FX6: TANI MAKMUR IV | FZ6: PADI WARAS 6 | GA6: NGUPADI HASIL 5 | GB6: GEMAH RIPAH 5 | GC6: BUDI KARYA 5
A7: Ngadirojo | B7: Desa Gunungsari | C7: Desa Petungsinarang | D7: Desa Kalak | E7: Desa Karangnongko | F7: Desa Pakisbaru | G7: Desa Hadiwarno | H7: Desa Kayen | I7: Desa Ngadirejan | J7: Desa Mendolo Kidul | K7: Desa Pager Lor | L7: Desa Ngreco | M7: Desa Kalikuning | O7: Subur | P7: Rukun Makmur IV | R7: Sumber Urip IV | S7: Margo Makmur IV | V7: Tani Maju IX | W7: Sumber Urip VI | X7: Rukun Tani V | Y7: Sido Mulyo IV | Z7: SIDO MAKMUR IX | AA7: Rukun Santoso II | AB7: MAKMUR RUKUN V | AC7: AKUR V | AD7: Guyup Rukun 05 | AE7: Kartini | AF7: MARGO MAKMUR | AG7: KARYA BAKTI | AH7: Margo Makmur | AI7: PERINTIS | AJ7: SIDO MAJU 1 | AK7: MARGO MULYO DUA | AL7: MUGI LESTARI | AM7: Karya Makmur II | AN7: Mardi Laras | AO7: Margo Makmur | AP7: Ngunduh Pakarti | AQ7: Sido Maju | AR7: Margo Rukun | AS7: Ngudi Karyo | AT7: Sri Rejeki | AU7: Sri Rejeki II | AV7: Sido Dadi | AW7: Langen Karyo | AX7: Sumber Agung | AZ7: Setyo Maju 7 | BA7: Tri Karsa 4 | BB7: Tani Maju 6 | BC7: Gotong Royong 6 | BD7: Sedyo Makmur 6 | BE7: Pratolo Mulyo 6 | BG7: Sido Mekar 6 | BH7: Sido Maju 6 | BI7: Sari Tani 6 | BL7: Ngudi Makmur 6 | BM7: Sumber Asri 6 | BN7: Setya Usaha VI | BO7: Bumi Harum 2 | BQ7: Sido Makmur 6 | BR7: Mugi Lancar | BS7: Lestari | BT7: Melati | BU7: Nawanggono III | BV7: Mawar | BW7: Muda Taruna Mandiri | BX7: Rukun Tani II | BY7: Marsudi Tani I | BZ7: Melati | CA7: Sumber Rejeki | CB7: MARDI RAHAYU V | CD7: RUKUN MAKMUR VI | CE7: PENI IV | CF7: TUNAS HARAPAN IX | CI7: BANGUNREJO V | CJ7: WIDYASANA IX | CK7: MARGO RUKUN VI | CO7: NGUDI MAKMUR V | CP7: SIDO MAKMUR VI | CU7: Gemah Ripah VI | CX7: Sumber Urip IV | DB7: Sedyo Rukun V | DD7: Margo Makmur IX | DE7: SIDO MAKMUR VI | DH7: ARGO MULYO V | DI7: Mekar Sari VI | DJ7: Mugi Rahayu VI | DK7: Sido Makmur IV | DL7: Sido Maju V | DR7: Nuju Makmur V | DS7: Suka Maju VI | DT7: Sakti V | DU7: Margo Mulyo VI | DV7: Selo Rejeki V | DW7: Sumber Rejeki IX | DX7: Sri Rejeki Lima | DY7: Lestari VI | DZ7: Karya Makmur | EA7: Sido Mulyo VI | EB7: Gemah Ripah VII | EC7: Sido Mulyo IX | ED7: Sido Mukti III | EE7: Ratih Tani III | EF7: Sendang Sari | EI7: Suko Makmur | EJ7: Rebo Kliwon II | EK7: Makaryo | EL7: Sri Rejeki | EM7: Margo Tresno | EN7: Pangupo Jiwo | EO7: Sido Dadi | EP7: Ringin Bakti | EQ7: Sido Tentrem | ER7: SUMBER REJEKI 3 | ES7: Subur Abadi | ET7: Sedya Mulya 6 | EU7: LAJUR SEMPU 5 | EV7: Pagergunung 2 | EW7: SUMBER REJEKI | EX7: Margo Mulyo 6 | EY7: Sido Maju | EZ7: NGUDI RAHAYU 2 | FA7: Ngudi Lestari 1 | FC7: GEMAH RIPAH 6 | FD7: AMONG TANI V | FF7: SIDO RUKUN IV | FG7: SUMBER TANI V | FH7: KARYA MAKMUR VI | FI7: RUKUN TANI I | FJ7: KARYA MAKMUR IV | FK7: SIDO RUKUN IV | FL7: HANDAYANI VII | FM7: NGUDI BOGO VI | FN7: KWT. BUNGUR ASRI | FP7: JATI MULYO 6 | FQ7: DARMA TANI VI | FR7: MARGO MULYO 4 | FS7: SUBUR MAKMUR VIII | FT7: HARJO MAKMUR 6 | FV7: MEKAR SARI 6 | FW7: Wanodyo Joyo | FX7: TANI MAKMUR V | FZ7: PADI WARAS I | GB7: GEMAH RIPAH 6 | GC7: BUDI KARYA 6
A8: Pacitan | B8: Desa Jatimalang | C8: Desa Tumpuk | D8: Desa Klepu Donorojo | E8: Desa Katipugal | F8: Desa Penggung | G8: Desa Ngadirojo | H8: Desa Kembang | I8: Desa Pelem | J8: Desa Mendolo Lor | K8: Desa Sembowo | L8: Desa Ploso (Tegalombo) | M8: Desa Ketro (Tulakan) | P8: Rukun Makmur V | R8: Sumber Urip V | V8: Tani Maju V | X8: Rukun Tani VI | Z8: SIDO MAKMUR V | AB8: MAKMUR RUKUN VI | AC8: AKUR VI | AD8: Guyup Rukun 06 | AE8: MAJU MAPAN | AF8: NGUDI MAKMUR | AG8: KARYA TANI | AH8: MARGO MULYO BARU | AI8: SEJAHTERA DUA | AJ8: SIDO MAKMUR | AK8: MARGO MULYO SATU | AL8: MULYA TANI | AM8: Karya Manunggal I | AN8: Margo Laras | AO8: Margo Mulyo | AP8: Padi Murni | AQ8: Tani Lestari | AR8: Margo Tentrem | AS8: Ngudi Makmur | AT8: Sumber Makmur | AU8: Sri Rejeki III | AV8: Sido Maju | AW8: Sido Muncul | AX8: Sumber Makmur | AZ8: Setyo Maju Dua | BA8: Tri Karsa 5 | BC8: Gotong Royong 7 | BD8: Sedyo Makmur 7 | BG8: Sido Mekar 7 | BH8: Sido Maju 7 | BI8: Sari Tani 7 | BL8: Ngudi Makmur 7 | BM8: Sumber Asri 7 | BN8: Setya Usaha VII | BO8: Bumi Harum 3 | BR8: Pelita Jaya | BS8: Nusa Indah | BT8: Sri Mulya | BU8: Sendang Mulyo | BV8: Ngudi Rahayu I | BW8: Ngudi Mulyo | BX8: Sari Mulyo I | BY8: Ngestu Tani | BZ8: Ngudi Makmur | CB8: MARDI RAHAYU VI | CD8: RUKUN MAKMUR VII | CE8: PENI V | CF8: TUNAS HARAPAN V | CI8: BANGUNREJO VI | CJ8: WIDYASANA V | CK8: MARGO RUKUN VII | CO8: NGUDI MAKMUR VI | CU8: KWT Mekar Sari | CX8: Sumber Urip V | DB8: Sedyo Rukun VI | DD8: Margo Makmur V | DE8: SIDO MAKMUR VII | DH8: ARGO MULYO VI | DI8: Mekar Sari VII | DJ8: Mugi Rahayu VII | DK8: Sido Makmur IX | DR8: Nuju Makmur VI | DT8: Sakti VI | DU8: Margo Mulyo VII | DV8: Selo Rejeki VI | DW8: Sumber Rejeki V | DX8: Sri Rejeki Sepuluh | DY8: Lestari VII | DZ8: Kembang Rejo | EB8: Gemah Ripah VIII | EC8: Sido Mulyo Nol Satu | ED8: Sido Mukti IV | EE8: Ratih Tani IV | EF8: Sri Rejeki | EI8: Tani Makmur | EJ8: Rebo Legi | EK8: Ngudi Makmur | EL8: Sumberejo | EM8: Margo Utomo | EN8: Punadirpa | EO8: Sido Mulyo I | EP8: Sido Mukti | EQ8: Sumber Makmur | ER8: TANI MAJU 1 | ES8: Suko Makmur | ET8: Sedya Mulya 7 | EU8: LAJUR SEMPU 6 | EV8: Tumpang Lestari | EW8: SUMBER URIP MULYO | EX8: Margo Rukun 1 | EY8: SIDO MAKMUR | EZ8: SALAM REJO | FA8: Ngudi Lestari 2 | FC8: GEMAH RIPAH 7 | FD8: AMONG TANI VI | FF8: SIDO RUKUN VI | FG8: SUMBER TANI VI | FH8: KARYA MAKMUR VII | FI8: RUKUN TANI MAJU | FJ8: KWT SUMBER WARAS | FL8: HANDAYANI VIII | FM8: NGUDI BOGO VII | FP8: JATI MULYO 7 | FR8: MARGO MULYO 5 | FV8: MEKAR SARI 7 | FX8: TANI MAKMUR VI | GB8: KWT ALAS SUBUR
A9: Pringkuku | B9: Desa Jetis Kidul | C9: Desa Watupatok | D9: Desa Sawahan | E9: Desa Kebonagung | F9: Desa Sempu | G9: Desa Nogosari | H9: Desa Menadi | I9: Desa Poko | J9: Desa Piton | K9: Desa Sudimoro | L9: Desa Pucangombo | M9: Desa Ketro Harjo | P9: Rukun Makmur VI | R9: Sumber Urip VI | V9: Tani Maju VI | X9: Rukun Tani VII | Z9: SIDO MAKMUR VI | AB9: MAKMUR RUKUN VII | AC9: AKUR VII | AE9: MARGO UTOMO | AF9: NGUDI REJEKI | AG9: NGUDI LUHUR | AH9: Mawar Putih | AI9: SEJAHTERA SATU | AJ9: SIDO MAKMUR 1 | AK9: MARGO MULYO TIGA | AL9: RUKUN TANI | AM9: Karya Manunggal II | AN9: Mugi Rahayu | AO9: Ngudi Mulyo | AP9: Rahayu Widodo | AR9: Sido Maju I | AS9: Ngudi Mulyo | AT9: Tani Mulyo | AU9: Sri Rejeki IV | AV9: Sido Makmur | AW9: Sidorejo | AX9: Sumber Rejeki | AZ9: Sido Makmur | BA9: Tri Karsa 6 | BC9: Gotong Royong 8 | BD9: Sedyo Makmur 8 | BH9: Winasri | BI9: Sari Tani 8 | BL9: Ngudi Makmur 8 | BO9: Bumi Harum 4 | BR9: Sumber Rejeki | BS9: Setya Karya | BT9: Sumber Dadi | BU9: Setya Karya | BV9: Ngudi Rahayu II | BW9: Rukun Santosa | BX9: Sari Mulyo II | BY9: Rahayu | BZ9: Ngudi Makmur II | CB9: MARDI RAHAYU VII | CE9: PENI VI | CF9: TUNAS HARAPAN VI | CI9: BANGUNREJO VII | CJ9: WIDYASANA VI | CO9: SIDO MAKMUR I | DD9: Margo Makmur VI | DE9: SIDO MAKMUR VIII | DH9: ARGO MULYO VII | DI9: Mekar Sari VIII | DK9: Sido Makmur V | DR9: Nuju Makmur VII | DT9: Sakti VII | DU9: Margo Mulyo VIII | DV9: Selo Rejeki VII | DW9: Sumber Rejeki VI | DX9: Sri Rejeki VI | DY9: Lestari VIII | DZ9: Maju Makmur | EB9: Gemah Ripah X | EC9: Sido Mulyo V | ED9: Sido Mukti V | EE9: Sedyo Rukun | EF9: Tambah Rejo | EI9: Tani Mulyo | EJ9: Tani Makmur | EK9: Sumber Makmur | EL9: Tani Mulyo I | EM9: Ngudi Mulyo | EN9: Purwodadi | EO9: Sido Mulyo II | ER9: TANI MAJU 2 | ET9: Sido Makmur 1 | EU9: MANDIRI | EV9: Wana Asri | EW9: TANI ASLI 1 | EX9: Margo Rukun 2 | EY9: Suko Makmur | EZ9: SEDYO MAJU | FA9: Ngudi Lestari 3 | FC9: KWT GEMAH LESTARI | FD9: AMONG TANI VII | FF9: TOMPAK MIJIL | FH9: KARYA MAKMUR VIII | FI9: SIDO MAKMUR | FJ9: KWT WANDIRA | FL9: KWT.TENGGAR ASRI | FM9: NGUDI BOGO VIII | FP9: JATI MULYO 8 | FR9: MARGO MULYO 6 | GB9: KWT ATSIRI JAYA
A10: Punung | B10: Desa Karanggede | D10: Desa Sekar | E10: Desa Ketepung | F10: Desa Tokawi | G10: Desa Pagerejo | H10: Desa Mentoro | I10: Desa Pringkuku | J10: Desa Ploso (Punung) | K10: Desa Sukorejo | L10: Desa Tahunan | M10: Desa Kluwih | V10: Tani Maju VII | Z10: SIDO MAKMUR VII | AB10: MAKMUR RUKUN VIII | AC10: AKUR VIII | AE10: Mbudidoyo | AF10: SARI BUMI | AG10: NGUDI MAKMUR | AH10: REJO MAKMUR | AI10: SETYA KARYA DUA | AJ10: SIDO MUKTI | AK10: MUDA TANI DUA | AL10: Sari Mulyo | AM10: Karya Tani | AN10: Ngudi Luhur | AO10: Ngudi Utomo | AP10: Sayuk Rukun | AR10: Sido Maju II | AS10: Ngudi Rahayu | AU10: Sumber Rejeki | AW10: Sumber Mulyo | BA10: Tri Karsa 7 | BC10: Gotong Royong 9 | BD10: Sedyo Makmur 9 | BI10: Sari Tani 9 | BO10: Bumi Harum 5 | BR10: Tani Maju | BS10: Sido Mulyo | BT10: Tani Mulya | BU10: Setya Tani | BV10: Sri Sedono | BW10: Seroja | BX10: Setya Tani | BY10: Sari Bumi | BZ10: Sari Bumi | CE10: PENI VII | CF10: TUNAS HARAPAN VII | CI10: BANGUNREJO VIII | CJ10: Widyasana VII | CO10: SIDO MAKMUR II | DD10: Margo Makmur VII | DH10: ARGO MULYO VIII | DK10: Sido Makmur VI | DR10: Nuju Makmur VIII | DT10: Sakti VIII | DV10: Selo Rejeki VIII | DW10: Sumber Rejeki VII | DX10: Sri Rejeki VII | DZ10: Pindul Makmur | EB10: Gemah Ripah XI | EC10: Sido Mulyo VI | ED10: Sido Mukti VII | EE10: Sido Makmur | EF10: Tani Maju | EI10: Tani Rukun | EL10: Tani Mulyo II | EM10: Rukun Tani | EN10: Subur Makmur | EO10: Sido Rukun I | ER10: TANI MAKMUR 1 | ET10: Sido Makmur 2 | EU10: MARGO MULYO 1 | EV10: Worawari 1 | EW10: TANI ASLI 2 | EX10: Margo Rukun 3 | EY10: Sumber Pangan | EZ10: SETYO TANI 1 | FA10: Selo Makmur 1 | FD10: AMONG TANI VIII | FH10: KWT HAYATI | FI10: SIDO TANI MAJU | FJ10: MARGO MAKMUR ABADI | FM10: RUKUN | FP10: JATI MULYO 9 | FR10: MARGO MULYO 7
A11: Sudimoro | B11: Desa Karangrejo | D11: Desa Sendang | E11: Desa Ketro (Kebonagung) | G11: Desa Sidomulyo (Ngadirojo) | H11: Desa Nanggungan | I11: Desa Sobo | J11: Desa Punung | K11: Desa Sumber Rejo | L11: Desa Tahunan Baru | M11: Desa Losari | V11: Tani Maju VIII | Z11: SIDO MAKMUR VIII | AB11: MAKMUR RUKUN X | AC11: AKUR X | AE11: Nggrening | AF11: SARI REJEKI | AG11: NGUDI RUKUN | AH11: REJO SARI | AI11: SETYA KARYA SATU | AJ11: SIDO MULYO | AK11: MUDA TANI SATU | AL11: SEDYO MULYO | AM11: Margo Makmur | AN11: Sedyo Mulyo | AO11: Padas Subur | AP11: Sri Rahayu | AR11: Sido Makmur | AS11: Ngudi Rejeki | AU11: Tani Rukun | AW11: Sumber Rejeki | BA11: Tri Karsa 8 | BC11: Sumber Makmur | BO11: Bumi Harum 6 | BS11: Sri Mulyo | BU11: Sido Makmur | BV11: Sumber Rejeki | BW11: SIDO MAKMUR | BX11: Sidorejo | BY11: Sido Makmur | BZ11: Sari Tani | CE11: PENI VIII | CF11: TUNAS HARAPAN VIII | CJ11: WIDYASANA VIII | CO11: SIDO MAKMUR III | DD11: Margo Makmur VIII | DH11: ARGO MULYO X | DK11: Sido Makmur VII | DR11: Nuju Makmur X | DT11: Sakti X | DV11: Selo Rejeki X | DW11: Sumber Rejeki VIII | DX11: Sri Rejeki VIII | DZ11: Sambi Rejo | EB11: Gemah Ripah XII | EC11: Sido Mulyo VII | EE11: Sri Mulyo | EF11: Tani Widodo | EL11: Tuhu Bakti I | EM11: Sedyo Rukun | EN11: Sumber Agung | EO11: Suka Maju | ER11: TANI MAKMUR 2 | ET11: Sumber Rejeki 1 | EU11: MARGO MULYO 2 | EV11: Worawari 2 | EW11: TANI MAJU 1 | EX11: Margo Rukun 4 | EY11: Sumber Rejeki 1 | EZ11: SETYO TANI 2 | FA11: Selo Makmur 2 | FD11: SAMPURNA ABADI | FH11: RUMAH TANI MAKMUR | FJ11: NGUDI REJEKI | FP11: KWT JATI ASRI | FR11: Suka Maju
A12: Tegalombo | B12: Desa Kedungbendo | D12: Desa Sukodono | E12: Desa Klesem | G12: Desa Tanjunglor | H12: Kelurahan Pacitan | I12: Desa Sugihwaras | J12: Desa Sooka | L12: Desa Tegalombo | M12: Desa Ngile | Z12: SIDO MAKMUR X | AC12: AKUR XI | AE12: NGGRENING DUA | AF12: SARI TANI | AG12: NGUDI SUBUR 01 | AH12: SIDO URIP | AI12: SETYA KARYA TIGA | AJ12: SIDO MULYO 1 | AK12: NGUDI MULYO | AL12: SEDYO RUKUN | AM12: Marsudi Makmur I | AN12: Sido Maju | AO12: Setyo Tuhu | AP12: Sri Rejeki | AS12: Ngudi Santoso | BA12: Tri Karsa 9 | BO12: Bumi Harum 7 | BS12: Sri Rejeki | BU12: Sri Lestari | BV12: Tani Makmur | BW12: SIDO RUKUN | BX12: Sinar pelita | BY12: Sri Tani | BZ12: SIDO DADI | CO12: SIDO MAKMUR IV | DH12: ARGO MULYO XI | DK12: Sido Makmur VIII | DR12: Nuju Makmur XI | DT12: Sakti XI | DX12: Sri Rejeki XI | DZ12: Sido Makmur I | EC12: Sido Mulyo VIII | EE12: Tani Mulyo | EL12: Tuhu Bakti II | EM12: Tani Maju | EN12: Sumber Agung Muda | ET12: Sumber Rejeki 2 | EU12: MARGO RUKUN | EW12: TANI MAJU 2 | EY12: Sumber Rejeki 2 | FA12: Swadaya Mandiri 1 | FH12: SIDO MAKMUR | FJ12: SIDO DADI GROGOL | FR12: TRI MULYO
A13: Tulakan | B13: Desa Mangunharjo | D13: Desa Widoro (Donorojo) | E13: Desa Mantren (Kebonagung) | G13: Desa Tanjungpuro | H13: Kelurahan Ploso | I13: Desa Tamanasri | J13: Desa Tinatar | M13: Desa Nglaran | Z13: SIDO MAKMUR XI | AC13: Akur XII | AE13: NGGRENING SATU | AF13: SETYA KAWAN | AG13: NGUDI SUBUR 02 | AH13: SRI REJEKI | AI13: SIDO DADI DUA | AJ13: SIDO MUNCUL | AK13: NGUDI TANI | AL13: SETYA TANI | AM13: Marsudi Makmur II | AN13: Sri Mulyo | AO13: Sido Mulyo | AP13: Sumber Rejeki | AS13: Ngudi Tani | BA13: TUNAS BARU | BO13: Bumi Harum 8 | BS13: Sumber Karya | BU13: Sri Rejeki | BW13: SINAR HARAPAN | BX13: Sinar Pelita I | BY13: Srikandi | BZ13: Sido Makmur | DH13: ARGO MULYO XII | DK13: Sido Makmur X | DR13: Nuju Makmur XII | DT13: Sakti XII | DX13: Sri Rejeki XII | DZ13: Sido Makmur II | EE13: Tani Rukun | EM13: Tani Murni | EN13: Sumber Asih | EU13: SIDO DADI 1 | EW13: TANI MAJU 3 | EY13: Sumber Tani | FA13: Swadaya Mandiri 2 | FH13: TANI BERKAH
B14: Desa Mlati | E14: Desa Plumbungan | G14: Desa Wiyoro | H14: Desa Ponggok | I14: Desa Watu Karung | J14: Desa Wareng | M14: Desa Ngumbul | AC14: AKUR XIII | AE14: NGUDI MULYO | AF14: SETYA TANI | AG14: NGUDI SUBUR III | AH14: SUMBER MAKMUR | AI14: SIDO DADI SATU | AJ14: SUKA MAJU | AK14: RAHAYU | AL14: SIDO RUKUN | AM14: Marsudi Makmur III | AN14: Sri Rahayu | AO14: SUMBER AGUNG | AP14: Tani Makmur | AS14: Rahayu | BO14: Bumi Harum 9 | BS14: Sumber Rejeki | BU14: Sri Rejeki II | BX14: Sinar Pelita II | BY14: Suka Tani | BZ14: Sido Makmur II | DK14: Sido Makmur XI | DR14: Nuju Makmur XIII | DT14: Sakti XIII | DX14: Sri Rejeki XIII | DZ14: Sido Makmur III | EN14: Tani Rukun | EU14: SIDO DADI 2 | EW14: USAHA TANI 1 | EY14: Tani Harapan | FA14: Wana Lestari 1 | FH14: TANI MAJU
B15: Desa Pagutan | E15: Desa Punjung | G15: Desa Wonoasri | H15: Kelurahan Pucangsewu | M15: Desa Padi | AE15: PETUNG | AF15: SIDO RUKUN | AG15: SARI REJEKI | AH15: SUMBER REJEKI | AI15: SIDO MAKMUR | AK15: RUKUN TANI | AL15: TAMAN TANI | AM15: Ngudi Makmur I | AN15: Sri Rejeki | AO15: Sumber Rejeki | AS15: Sumber Rejeki | BS15: Sumber Sari | BU15: Sri Sadono | BX15: Tunas Subur | BY15: Tani Sido Makmur | BZ15: Sido Rukun | DR15: Nuju Makmur XIV | DT15: Sakti XIV | DX15: Sri Rejeki XIV | DZ15: Tani Mulya | EU15: SUMBER LANCAR | EW15: USAHA TANI 2 | EY15: Tani Makmur | FA15: Wana Lestari 2 | FH15: TANI MAKMUR
B16: Desa Sedayu | E16: Desa Purwoasri | G16: Desa Wonodadi Kulon | H16: Desa Purworejo | M16: Desa Tulakan | AE16: REJO MULYO | AF16: SUMBER MULYO | AG16: SIDO LUHUR | AH16: TUNAS MANUNGGAL | AI16: SIDO MULYO | AK16: SERBA TANI | AL16: TANI RUKUN SATU | AM16: Ngudi Makmur II | AO16: Tani Rukun | AS16: Sumber Rejo | DR16: Nuju Makmur XV | DT16: Sakti XIX | DZ16: Wayah Makmur | EU16: TANI SUBUR | EY16: Tani Mulyo | FH16: TANI MULYA
B17: Desa Temon | E17: Desa Sanggrahan | G17: Desa Wonodadi Wetan | H17: Desa Sambong | M17: Desa Wonoanti | AE17: SARI MULYO | AF17: SUMBER REJEKI | AG17: SIDO MAKMUR | AI17: TERATAI | AL17: WARGO TANI II | AM17: Ngudi Rahayu | AO17: WANA BOGA | AS17: Tani Maju | DR17: Nuju Makmur XVI | DT17: Sakti XV | EY17: Tani Murni | FH17: TANI SEJAHTERA
B18: Desa Tremas | E18: Desa Sidomulyo (Kebonagung) | G18: Desa Wonokarto | H18: Desa Sedeng | M18: Desa Wonosidi | AE18: SARI MULYO I | AF18: SUMBER URIP | AG18: SIDO RUKUN | AL18: WARGO TANI SATU | AM18: Sido Maju I | AS18: Tani Mulyo | DR18: Nuju Makmur XVI A | DT18: Sakti XVI | EY18: Tunas Harapan
E19: Desa Wonogondo | G19: Desa Wonosobo | H19: Desa Semanten | AE19: SIDO MAJU | AF19: TANI MAKMUR | AG19: SUMBER REJEKI | AM19: Sido Maju II | DT19: Sakti XVII | EY19: Usaha Tani
E20: Desa Worawari | H20: Kelurahan Sidoharjo | AE20: SIDO MAKMUR | AF20: TANI MULYO | AG20: TANI LESTARI | AM20: Sido Makmur | DT20: Sakti XVIII
H21: Desa Sirnoboyo | AE21: SIDO MAKMUR 4 | AF21: UNGGUL | AG21: TANI SUBUR 01 | AM21: Wana Lestari
H22: Desa Sukoharjo | AE22: Suroloyo | AF22: WIDODO MULYO | AG22: TANI SUBUR 02
H23: Desa Sumberharjo | AE23: Suroloyo I | AG23: TANI UTOMO
H24: Desa Tambakrejo | AG24: WARGO RUKUN
H25: Desa Tanjungsari
H26: Desa Widoro (Pacitan)
H30: Kelurahan Baleharjo
H31: Kelurahan Pacitan
H32: Kelurahan Ploso
H33: Kelurahan Pucangsewu
H34: Kelurahan Sidoharjo
H35: Desa Arjowinangun
H36: Desa Bangunsari
H37: Desa Banjarsari
H38: Desa Bolosingo
H39: Desa Kayen
... H54: Desa Widoro

Sheet Data Poktan List
A1: Desa Arjosari | B1: Desa Borang | C1: Desa Gayuhan | D1: Desa Gegeran | E1: Desa Gembong | F1: Desa Gunungsari | G1: Desa Jatimalang | H1: Desa Jetis Kidul | I1: Desa Karanggede | J1: Desa Karangrejo | K1: Desa Kedungbendo | L1: Desa Mangunharjo | M1: Desa Mlati | N1: Desa Pagutan | O1: Desa Sedayu | P1: Desa Temon | Q1: Desa Tremas | R1: Desa Bandar | S1: Desa Bangunsari Bandar | T1: Desa Jeruk | U1: Desa Kledung | V1: Desa Ngunut | W1: Desa Petungsinarang | X1: Desa Tumpuk | Y1: Desa Watupatok | Z1: Desa Belah | AA1: Desa Cemeng | AB1: Desa Donorojo | AC1: Desa Gedompol | AD1: Desa Gendaran | AE1: Desa Kalak | AF1: Desa Klepu Donorojo | AG1: Desa Sawahan | AH1: Desa Sekar | AI1: Desa Sendang | AJ1: Desa Sukodono | AK1: Desa Widoro (Donorojo) | AL1: Desa Banjarjo | AM1: Desa Gawang | AN1: Desa Gembuk | AO1: Desa Kalipelus | AP1: Desa Karanganyar | AQ1: Desa Karangnongko | AR1: Desa Katipugal | AS1: Desa Kebonagung | AT1: Desa Ketepung | AU1: Desa Ketro (Kebonagung) | AV1: Desa Klesem | AW1: Desa Mantren (Kebonagung) | AX1: Desa Plumbungan | AY1: Desa Punjung | AZ1: Desa Purwoasri | BA1: Desa Sanggrahan | BB1: Desa Sidomulyo (Kebonagung) | BC1: Desa Wonogondo | BD1: Desa Worawari | BE1: Desa Gondang | BF1: Desa Jetislor | BG1: Desa Mujing | BH1: Desa Nawangan | BI1: Desa Ngromo | BJ1: Desa Pakisbaru | BK1: Desa Penggung | BL1: Desa Sempu | BM1: Desa Tokawi | BN1: Desa Bodag | BO1: Desa Bogoharjo | BP1: Desa Cangkring | BQ1: Desa Cokrokembang | BR1: Desa Hadiluwih | BS1: Desa Hadiwarno | BT1: Desa Ngadirojo | BU1: Desa Nogosari | BV1: Desa Pagerejo | BW1: Desa Sidomulyo (Ngadirojo) | BX1: Desa Tanjunglor | BY1: Desa Tanjungpuro | BZ1: Desa Wiyoro | CA1: Desa Wonoasri | CB1: Desa Wonodadi Kulon | CC1: Desa Wonodadi Wetan | CD1: Desa Wonokarto | CE1: Desa Wonosobo | CF1: Desa Arjowinangun | CG1: Kelurahan Baleharjo | CH1: Desa Bangunsari (Pacitan) | CI1: Desa Banjarsari | CJ1: Desa Bolosingo | CK1: Desa Kayen | CL1: Desa Kembang | CM1: Desa Menadi | CN1: Desa Mentoro | CO1: Desa Nanggungan | CP1: Kelurahan Pacitan | CQ1: Kelurahan Ploso | CR1: Desa Ponggok | CS1: Kelurahan Pucangsewu | CT1: Desa Purworejo | CU1: Desa Sambong | CV1: Desa Sedeng | CW1: Desa Semanten | CX1: Kelurahan Sidoharjo | CY1: Desa Sirnoboyo | CZ1: Desa Sukoharjo | DA1: Desa Sumberharjo | DB1: Desa Tambakrejo | DC1: Desa Tanjungsari | DD1: Desa Widoro (Pacitan) | DE1: Desa Candi | DF1: Desa Dadapan | DG1: Desa Dersono | DH1: Desa Glinggangan | DI1: Desa Jlubang | DJ1: Desa Ngadirejan | DK1: Desa Pelem | DL1: Desa Poko | DM1: Desa Pringkuku | DN1: Desa Sobo | DO1: Desa Sugihwaras | DP1: Desa Tamanasri | DQ1: Desa Watu Karung | DR1: Desa Bomo | DS1: Desa Gondosari | DT1: Desa Kebonsari | DU1: Desa Kendal | DV1: Desa Mantren (Punung) | DW1: Desa Mendolo Kidul | DX1: Desa Mendolo Lor | DY1: Desa Piton | DZ1: Desa Ploso (Punung) | EA1: Desa Punung | EB1: Desa Sooka | EC1: Desa Tinatar | ED1: Desa Wareng | EE1: Desa Gunung Rejo | EF1: Desa Karang Mulyo | EG1: Desa Ketanggung | EH1: Desa Klepu (Sudimoro) | EI1: Desa Pager Kidul | EJ1: Desa Pager Lor | EK1: Desa Sembowo | EL1: Desa Sudimoro | EM1: Desa Sukorejo | EN1: Desa Sumber Rejo | EO1: Desa Gedangan | EP1: Desa Gemaharjo | EQ1: Desa Kasihan | ER1: Desa Kebondalem | ES1: Desa Kemuning | ET1: Desa Ngreco | EU1: Desa Ploso (Tegalombo) | EV1: Desa Pucangombo | EW1: Desa Tahunan | EX1: Desa Tahunan Baru | EY1: Desa Tegalombo | EZ1: Desa Bubakan | FA1: Desa Bungur | FB1: Desa Gasang | FC1: Desa Jatigunung | FD1: Desa Jetak | FE1: Desa Kalikuning | FF1: Desa Ketro (Tulakan) | FG1: Desa Ketro Harjo | FH1: Desa Kluwih | FI1: Desa Losari | FJ1: Desa Ngile | FK1: Desa Nglaran | FL1: Desa Ngumbul | FM1: Desa Padi | FN1: Desa Tulakan | FO1: Desa Wonoanti | FP1: Desa Wonosidi
A2: KWT Ngudi Rejeki Lancar | B2: KWT Sido Lestari | C2: KWT Gayuh Sehat I | D2: KWT Tani Maju | E2: KWT Sumber Urip I | F2: KWT Dahlia | G2: KWT Eka Mandiri | H2: Sido Subur I | I2: KWT Mawar | J2: Sumber Urip I | K2: KWT Sido Makmur | L2: KWT Dahlia | M2: KWT SEKAR TANJUNG | N2: KWT MAWAR | O2: MAKMUR RUKUN I | P2: AKUR I | Q2: KWT PERTIWI | R2: BINTANG TIMUR | S2: BLIMBING TANI | T2: BUDI LUHUR | U2: BLOROK MADU | V2: KWT. MELATI | W2: KENANGA I | X2: ANGGIAT TANI | Y2: DADI MAKMUR | Z2: Dadi Makmur | AA2: Edi Peni | AB2: Jati Diri | AC2: Budi Lestari | AD2: Dadi Mulyo | AE2: KWT. KELAPA SARI | AF2: Loh Jinawi | AG2: Bakti Tani | AH2: KWT Sekar Arum Sejahtera | AI2: Gebang Wonokarto | AJ2: Assalam | AK2: Lestari | AL2: Sumber Makmur 1 | AM2: Setyo Maju 1 | AN2: Tri Karsa 1 | AO2: Tani Maju 1 | AP2: Gotong Royong 1 | AQ2: Sedyo Makmur 1 | AR2: Pratolo Mulyo 1 | AS2: Mentes 1 | AT2: Sido Mekar 1 | AU2: Sido Maju 1 | AV2: Sari Tani 1 | AW2: Margo Subur 1 | AX2: Lestari I | AY2: Ngudi Makmur 1 | AZ2: Sumber Asri 1 | BA2: Setya Usaha I | BB2: Bumi Harum 1 | BC2: Sido Rejo 1 | BD2: Sido Makmur 1 | BE2: Dewi Sinto | BF2: Dewi Sri | BG2: Karya Makmur I | BH2: Ledok Sari | BI2: Arum Tani | BJ2: BARU WUNGU | BK2: Karya Makmur | BL2: Berkah Tani | BM2: Gemah Ripah | BN2: NGUDI LUHUR I | BO2: KWT MARDI RAHAYU | BP2: SUKODONO I | BQ2: RUKUN MAKMUR I | BR2: Melati | BS2: Matahari | BT2: MEKARSARI I | BU2: KARYA MULYA I | BV2: BANGUNREJO I | BW2: KWT. LESTARI MULYO | BX2: MARGO RUKUN I | BY2: MAKMUR I | BZ2: MARDI REJO I | CA2: ERAS ASRI I | CB2: DHARMA BAKTI | CC2: SIDO MAKMUR I | CD2: ERAS I | CE2: ERAS SOBO 5 | CF2: Sido Asih I | CG2: Eko Proyo I | CH2: Gemah Ripah I | CI2: KWT Melati | CJ2: Utama Karya I | CK2: KWT Karya Makmur | CL2: Sido Mekar 1 | CM2: KWT SRIKANDI | CN2: Sedyo Tani I | CO2: KWT PADEMANGAN PUTRI | CP2: MANUNGGAL I | CQ2: KWT Margo Makmur VI A | CR2: SIDO MAKMUR I | CS2: KARYO TOMO I | CT2: KWT Sido Dadi | CU2: ARGO MULYO I | CV2: Mekar Sari I | CW2: Mugi Rahayu I | CX2: KWT Bina Makmur | CY2: KWT Mekar Sari | CZ2: KWT Sido Rukun | DA2: KWT Rejo Mulyo | DB2: Karya Tani I | DC2: Karya Tunggal I | DD2: KWT SIDO MAPAN | DE2: Nuju Makmur 01 | DF2: Suka Maju 01 | DG2: Sakti I | DH2: Margo Mulyo 01 | DI2: Selo Rejeki I | DJ2: Blimbing Sari | DK2: Sri Rejeki I | DL2: Lestari I | DM2: JANTI MAKMUR | DN2: Sido Mulyo I | DO2: Gemah Ripah I | DP2: SIDO MULYO SEPULUH | DQ2: KWT Sido Mukti 4 | DR2: KWT Manunggal Mukti | DS2: Maju Lancar | DT2: Harapan | DU2: Tani Harapan | DV2: Fajar Rahayu | DW2: Karya Luhur I | DX2: Basuki Makmur | DY2: Budi Luhur | DZ2: Amanah | EA2: Karya Tani | EB2: Mardi Utomo | EC2: Ayem Tentrem | ED2: Eko Budoyo | EE2: MEKAR SARI 1 | EF2: KWT. SRI TANJUNG | EG2: Sedya Mulya 1 | EH2: BATU GUNA | EI2: Kutilang 1 | EJ2: KARYA TANI | EK2: Margo Mulyo 1 | EL2: KWT. SRIKANDI | EM2: KWT Kali Rejo | EN2: SIDO LANCAR | EO2: RUKUN TANI I | EP2: GEMAH RIPAH 1 | EQ2: AMONG TANI I | ER2: SEDYO MAJU I | ES2: PUNCAK SEWU | ET2: KWT LUMBU INDAH | EU2: KARYA MAKMUR I | EV2: MANDIRI MAPAN | EW2: AL-FATTAH | EX2: GONDO ARUM | EY2: HANDAYANI I | EZ2: NGUDI BOGO I | FA2: KARYA TANI I | FB2: MARGO MAKMUR I | FC2: JATI MULYO 1 | FD2: DARMA TANI I | FE2: KWT Sido Lancar | FF2: SUBUR MAKMUR 1 | FG2: HARJO MAKMUR 1 | FH2: SETYA KARYA DUA | FI2: MEKAR SARI 1 | FJ2: EDI PENI I | FK2: KWT. JAMU SEGER MANIS | FL2: WALUYO ASIH I | FM2: PADI WARAS 2 | FN2: NGUPADI HASIL 1 | FO2: GEMAH RIPAH 1 | FP2: BUDI KARYA 1
A3: Adil Makmur I | B3: Sido Rukun I | C3: KWT Gayuh Sehat II | D3: Sido Dadi | E3: KWT Sumber Urip II | F3: KWT Melati Putih | G3: Lestari I | H3: Sido Subur II | I3: Tani Maju I | J3: Sumber Urip II | K3: Rukun III | L3: Sido Mulyo I | M3: SIDO MAKMUR I | N3: Rukun Santosa 01 | O3: MAKMUR RUKUN II | P3: AKUR II | Q3: Guyup Rukun 01 | R3: EDI PENI | S3: CIPTO TANI | T3: BUDI UTOMO | U3: ENGGAL LESTARI | V3: LESTARI | W3: KENANGA II | X3: KENANGA | Y3: GUNUNG SARI DUA | Z3: Hasil Tani | AA3: Eko Makaryo | AB3: Karya Bakti | AC3: Mardi Makmur I | AD3: KWT Karya Maju | AE3: Barokah | AF3: Makmur | AG3: Budi Luhur | AH3: Ngudi Rahayu | AI3: Makmur | AJ3: Budi Mulyo | AK3: Ngudi Makmur | AL3: Sumber Makmur 2 | AM3: Setyo Maju 3 | AN3: Tri Karsa 10 | AO3: Tani Maju 2 | AP3: Gotong Royong 2 | AQ3: Sedyo Makmur 2 | AR3: Pratolo Mulyo 2 | AS3: Mentes 2 | AT3: Sido Mekar 2 | AU3: Sido Maju 2 | AV3: Sari Tani 2 | AW3: Margo Subur 2 | AX3: Lestari II | AY3: Ngudi Makmur 2 | AZ3: Sumber Asri 2 | BA3: Setya Usaha II | BB3: Bumi Harum 10 | BC3: Sido Rejo 2 | BD3: Sido Makmur 2 | BE3: Dewi Sri | BF3: Dono Asih | BG3: Karya Makmur II | BH3: Manunggal Karya | BI3: Bina Tani I | BJ3: HARGO MULYO | BK3: Lestari | BL3: Karya Muda | BM3: Hidayah | BN3: NGUDI LUHUR II | BO3: MARDI RAHAYU I | BP3: SUKODONO II | BQ3: RUKUN MAKMUR II | BR3: PENI | BS3: TUNAS HARAPAN I | BT3: MEKARSARI II | BU3: KARYA MULYA II | BV3: BANGUNREJO II | BW3: WIDYASANA I | BX3: MARGO RUKUN II | BY3: MAKMUR II | BZ3: MARDI REJO II | CA3: ERAS ASRI II | CB3: NGUDI MAKMUR I | CC3: SIDO MAKMUR II | CD3: ERAS II | CE3: ERAS SOBO I | CF3: Sido Asih II | CG3: Eko Proyo II | CH3: Gemah Ripah II | CI3: Sido Dadi I | CJ3: Utama Karya II | CK3: KWT Sumber Rejeki | CL3: Sido Mekar 2 | CM3: Gemah Ripah I | CN3: Sedyo Tani II | CO3: Sedyo Rukun I | CP3: Manunggal II | CQ3: Margo Makmur I | CR3: SIDO MAKMUR II | CS3: KARYO TOMO II | CT3: Margo Mulyo I | CU3: ARGO MULYO II | CV3: Mekar Sari II | CW3: Mugi Rahayu II | CX3: KWT Mekar Makmur | CY3: Sido Maju I | CZ3: Sido Rukun I | DA3: KWT Tani Maju | DB3: Karya Tani II | DC3: Karya Tunggal II | DD3: Sidodadi I | DE3: Nuju Makmur II | DF3: Suka Maju 05 | DG3: Sakti II | DH3: Margo Mulyo 05 | DI3: Selo Rejeki II | DJ3: KWT. Rindang | DK3: Sri Rejeki II | DL3: Lestari II | DM3: Gondang Rejo I | DN3: Sido Mulyo II | DO3: Gemah Ripah II | DP3: KWT. Budi Lestari | DQ3: KWT Sido Mukti I | DR3: Manunggal Mukti | DS3: Margo Dadi | DT3: Lestari | DU3: Tani Makmur | DV3: Handayani | DW3: Karya Luhur II | DX3: Eko Karyo | DY3: Karya Tani | DZ3: Hidayah | EA3: Maju Lancar I | EB3: Mardi Waluyo I | EC3: Bakti Utomo | ED3: Ngudi Makmur | EE3: MEKAR SARI 2 | EF3: Margo Mulyo | EG3: Sedya Mulya 2 | EH3: LAJUR SEMPU 1 | EI3: Kutilang 2 | EJ3: NGUDI MULYO 1 | EK3: Margo Mulyo 2 | EL3: Mijil Pangan | EM3: KWT Marsudi Tani | EN3: Duren Manis 1 | EO3: RUKUN TANI II | EP3: GEMAH RIPAH 2 | EQ3: AMONG TANI II | ER3: SEDYO MAJU II | ES3: SIDO MAKMUR I | ET3: SUMBER TANI I | EU3: KARYA MAKMUR II | EV3: MEKAR DADI | EW3: BUMI RAHAYU | EX3: KWT LESTARI | EY3: HANDAYANI II | EZ3: NGUDI BOGO II | FA3: KARYA TANI II | FB3: MARGO MAKMUR II | FC3: JATI MULYO 2 | FD3: DARMA TANI II | FE3: MARGO MULYO 1 | FF3: SUBUR MAKMUR 2 | FG3: HARJO MAKMUR 2 | FH3: SETYA KARYA EMPAT | FI3: MEKAR SARI 2 | FJ3: EDI PENI II | FK3: TANI MAKMUR 1 | FL3: WALUYO ASIH II | FM3: PADI WARAS 3 | FN3: NGUPADI HASIL 2 | FO3: GEMAH RIPAH 2 | FP3: BUDI KARYA 2
A4: Adil Makmur II | B4: Sido Rukun II | C4: Rukun Makmur I | D4: Sido Makmur | E4: Sumber Urip I | F4: Margo Makmur I | G4: Lestari II | H4: Sido Subur III | I4: Tani Maju II | J4: Sumber Urip III | K4: Rukun Tani I | L4: Sido Mulyo IB | M4: SIDO MAKMUR II | N4: Rukun Santosa III | O4: MAKMUR RUKUN III | P4: AKUR III | Q4: Guyup Rukun 02 | R4: EKO SAYEKTI | S4: DADI MAKMUR | T4: GUNUNG SUBUR | U4: JATI SARI | V4: MAKMUR DUA | W4: SIDO DADI | X4: MARGO MAKMUR DUA | Y4: GUNUNG SARI SATU | Z4: Karya Bima | AA4: Gawe Santoso | AB4: Karya Tani | AC4: Mardi Makmur II | AD4: Margi Laras | AE4: Dadi Makmur | AF4: Margo Mulyo | AG4: Margo Mulyo | AH4: Sido Dadi I | AI4: Manunggal Bakti | AJ4: Dadi Subur | AK4: Sido Makmur | AL4: Sumber Makmur 3 | AM4: Setyo Maju 4 | AN4: Tri Karsa 11 | AO4: Tani Maju 3 | AP4: Gotong Royong 3 | AQ4: Sedyo Makmur 3 | AR4: Pratolo Mulyo 3 | AS4: Mentes 3 | AT4: Sido Mekar 3 | AU4: Sido Maju 3 | AV4: Sari Tani 3 | AW4: Margo Subur 3 | AX4: Lestari III | AY4: Ngudi Makmur 3 | AZ4: Sumber Asri 3 | BA4: Setya Usaha III | BB4: Bumi Harum 11 | BC4: Sido Rejo 3 | BD4: Sido Makmur 3 | BE4: Hargo Sedah | BF4: Indah Karya I | BG4: Margo Rahayu | BH4: Mawar | BI4: Bina Tani II | BJ4: Lestari Mulyo | BK4: Ngudi Boga | BL4: Maju Tani | BM4: Karya Makmur | BN4: NGUDI LUHUR III | BO4: MARDI RAHAYU II | BP4: SUKODONO III | BQ4: RUKUN MAKMUR III | BR4: PENI I | BS4: TUNAS HARAPAN II | BT4: MEKARSARI III | BU4: KARYA MULYA III | BV4: BANGUNREJO III | BW4: WIDYASANA II | BX4: MARGO RUKUN III | BY4: MAKMUR III | BZ4: MARDI REJO III | CA4: ERAS ASRI III | CB4: NGUDI MAKMUR II | CC4: SIDO MAKMUR III | CD4: ERAS III | CE4: ERAS SOBO II | CF4: Sido Asih III | CG4: KWT Sakura III | CH4: Gemah Ripah III | CI4: Sido Dadi II | CJ4: Utama Karya III | CK4: Sumber Urip I | CL4: Sido Mekar 3 | CM4: Gemah Ripah II | CN4: Sedyo Tani III | CO4: Sedyo Rukun II | CQ4: Margo Makmur II | CR4: SIDO MAKMUR III | CT4: Margo Mulyo II | CU4: ARGO MULYO III | CV4: Mekar Sari III | CW4: Mugi Rahayu III | CX4: Sido Makmur I | CY4: Sido Maju II | CZ4: Sido Rukun II | DA4: Sumber Makmur I | DB4: Karya Tani III | DC4: Karya Tunggal III | DD4: Sidodadi II | DE4: Nuju Makmur III | DF4: Suka Maju II | DG4: Sakti III | DH4: Margo Mulyo II | DI4: Selo Rejeki III | DJ4: Sumber Rejeki Dua | DK4: Sri Rejeki III | DL4: Lestari III | DM4: Gondang Rejo II | DN4: Sido Mulyo III | DO4: Gemah Ripah III | DP4: Sido Mulyo II | DQ4: Margo Mukti | DR4: Marsudi Tani | DS4: Margo Tani | DT4: Ngudi Makmur | DU4: Tani Mulyo | DV4: Ngudi Rukun | DW4: Karya Tani | DX4: Handayani | DY4: Rukun Tani | DZ4: Kurnia | EA4: Maju Lancar II | EB4: Mardi Waluyo II | EC4: Budi Lestari | ED4: Sido Dadi | EE4: MEKAR SARI 3 | EF4: Margo Rukun | EG4: Sedya Mulya 3 | EH4: LAJUR SEMPU 2 | EI4: Lumpang Bogo 1 | EJ4: NGUDI MULYO 2 | EK4: Margo Mulyo 3 | EL4: Ngudi Makmur | EM4: MARSUDI TANI 1 | EN4: Duren Manis 2 | EO4: RUKUN TANI III | EP4: GEMAH RIPAH 3 | EQ4: AMONG TANI III | ER4: SEDYO MAJU III | ES4: SIDO MAKMUR II | ET4: SUMBER TANI II | EU4: KARYA MAKMUR III | EV4: RUKUN TANI 2 | EW4: KARYA MAKMUR I | EX4: SIDO RUKUN I | EY4: HANDAYANI IV | EZ4: NGUDI BOGO III | FA4: KARYA TANI III | FB4: MARGO MAKMUR III | FC4: JATI MULYO 3 | FD4: DARMA TANI III | FE4: Margo Mulyo 10 | FF4: SUBUR MAKMUR IV | FG4: HARJO MAKMUR 3 | FH4: SETYA KARYA SATU | FI4: MEKAR SARI 3 | FJ4: EDI PENI III | FK4: TANI MAKMUR II | FL4: WALUYO ASIH III | FM4: PADI WARAS 4 | FN4: NGUPADI HASIL 3 | FO4: GEMAH RIPAH 3 | FP4: BUDI KARYA 3
A5: Adil Makmur III | B5: Sido Rukun III | C5: Rukun Makmur II | D5: Sido Mulyo | E5: Sumber Urip II | F5: Margo Makmur II | G5: Lestari III | H5: Sido Subur IV | I5: Tani Maju III | J5: Sumber Urip IV | K5: Rukun Tani II | L5: Sido Mulyo II | M5: SIDO MAKMUR III | N5: Rukun Santosa IV | O5: MAKMUR RUKUN IV | P5: AKUR IV | Q5: Guyup Rukun 03 | R5: GUNUNG SUBUR | S5: ENDAH PENI | T5: HARGO MAKMUR | U5: KARYA TUNGGAL | V5: MAKMUR SATU | W5: SIDO DADI 1 | X5: MARGO MAKMUR SATU | Y5: MEKAR DADI | Z5: Karya Makmur | AA5: Gotong Royong | AB5: KWT Mekar Sari | AC5: Mardi Makmur III | AD5: Margo Mulyo | AE5: Dadi Mulyo | AF5: Mekar Sari | AG5: Rukun Makmur | AH5: Sido Dadi II | AI5: Rukun Tani | AJ5: Giri Mulyo | AK5: Sido Tani | AL5: Sumber Makmur 4 | AM5: Setyo Maju 5 | AN5: Tri Karsa 2 | AO5: Tani Maju 4 | AP5: Gotong Royong 4 | AQ5: Sedyo Makmur 4 | AR5: Pratolo Mulyo 4 | AT5: Sido Mekar 4 | AU5: Sido Maju 4 | AV5: Sari Tani 4 | AW5: Margo Subur 4 | AX5: Lestari IV | AY5: Ngudi Makmur 4 | AZ5: Sumber Asri 4 | BA5: Setya Usaha IV | BB5: Bumi Harum 12 | BC5: Sido Rejo 4 | BD5: Sido Makmur 4 | BE5: Karya Mandiri | BF5: Karya Bakti | BG5: Margo Rahayu 2 | BH5: Nawanggono | BI5: Bina Tani III | BJ5: MARGO MULYO | BK5: Ngudi Luhur | BL5: MARSUDI SUBUR | BM5: Karya Tani | BN5: NGUDI LUHUR IV | BO5: MARDI RAHAYU III | BP5: SUKODONO IV | BQ5: RUKUN MAKMUR IV | BR5: PENI II | BS5: TUNAS HARAPAN III | BT5: MEKARSARI IV | BU5: KARYA MULYA IV | BV5: BANGUNREJO IV | BW5: WIDYASANA III | BX5: MARGO RUKUN IV | BY5: MAKMUR IV | BZ5: MARDI REJO IV | CA5: ERAS ASRI IV | CB5: NGUDI MAKMUR III | CC5: SIDO MAKMUR IV | CD5: ERAS IV | CE5: ERAS SOBO III | CF5: Sido Asih IV | CH5: Gemah Ripah IV | CI5: Sido Dadi III | CJ5: Utama Karya IV | CK5: Sumber Urip II | CL5: Sido Mekar 4 | CM5: Gemah Ripah III | CO5: Sedyo Rukun III | CQ5: Margo Makmur III | CR5: SIDO MAKMUR IV | CT5: Margo Mulyo III | CU5: ARGO MULYO IV | CV5: Mekar Sari IV | CW5: Mugi Rahayu IV | CX5: Sido Makmur II | CY5: Sido Maju III | CZ5: Sido Rukun III | DA5: Sumber Makmur II | DB5: KWT Dewi Sri | DC5: KWT Sri Tanjung | DD5: Sidodadi III | DE5: Nuju Makmur IV | DF5: Suka Maju III | DG5: Sakti IV | DH5: Margo Mulyo III | DI5: Selo Rejeki IV | DJ5: Sumber Rejeki III | DK5: Sri Rejeki IV | DL5: Lestari IV | DM5: Gondang Rejo V | DN5: Sido Mulyo IV | DO5: Gemah Ripah IX | DP5: Sido Mulyo III | DQ5: Sido Mukti I | DR5: Mekar Sari | DS5: Rahayu | DT5: Sido Dadi | DU5: Tani Murni | DV5: Rukun Mulyo | DW5: Margo Tresno | DX5: Karya Bakti | DY5: Sido Luhur | DZ5: Margo Asih | EA5: Margo Mulyo | EB5: Margo Gesang | EC5: Karya Makmur | ED5: Sido Makmur | EE5: SUMBER REJEKI 1 | EF5: Sido Dadi 1 | EG5: Sedya Mulya 4 | EH5: LAJUR SEMPU 3 | EI5: Lumpang Bogo 2 | EJ5: NGUDI TANI | EK5: Margo Mulyo 4 | EL5: Ngudi Mulyo 1 | EM5: MARSUDI TANI 2 | EN5: KWT Ngudi Rahayu | EP5: GEMAH RIPAH 4 | EQ5: AMONG TANI IV | ER5: SEDYO MAJU IV | ES5: SIDO MAKMUR IV | ET5: SUMBER TANI III | EU5: KARYA MAKMUR IV | EV5: RUKUN TANI 3 | EW5: KARYA MAKMUR II | EX5: SIDO RUKUN II | EY5: HANDAYANI V | EZ5: NGUDI BOGO IV | FA5: KARYA TANI IV | FC5: JATI MULYO 4 | FD5: DARMA TANI IV | FE5: MARGO MULYO 2 | FF5: SUBUR MAKMUR IX | FG5: HARJO MAKMUR 4 | FH5: SETYA KARYA TIGA | FI5: MEKAR SARI 4 | FJ5: EDI PENI IV | FK5: TANI MAKMUR III | FL5: WALUYO ASIH IV | FM5: PADI WARAS 5 | FN5: NGUPADI HASIL 4 | FO5: GEMAH RIPAH 4 | FP5: BUDI KARYA 4
